Workbook

Sheet Dashboard
A1: MAHJONG × BLOCK — MARKET RESEARCH DASHBOARD
A2: Snapshot từ 73 game | Lens: scale, momentum, monetization proxy, recency
A4: BLOCK MARKET | D4: MAHJONG MARKET
A5: Số game | B5: ='So sánh'!B4 -> 49 | D5: Số game | E5: ='So sánh'!C4 -> 24
A6: Tổng downloads | B6: ='So sánh'!B5 -> 50634623 | D6: Tổng downloads | E6: ='So sánh'!C5 -> 25960544
A7: Tổng revenue | B7: ='So sánh'!B8 -> 17308927 | D7: Tổng revenue | E7: ='So sánh'!C8 -> 978960.23
A8: Weighted DL growth | B8: ='So sánh'!B10 -> 0.0046775644 | D8: Weighted DL growth | E8: ='So sánh'!C10 -> 0.04510079
A9: Positive growth share | B9: ='So sánh'!B11 -> 0.35555556 | D9: Positive growth share | E9: ='So sánh'!C11 -> 0.57142857
A12: HYBRID OPPORTUNITY
A13: Evidence | B13: Block có scale downloads lớn hơn; Mahjong có momentum rộng hơn.
A14: Design hypothesis | B14: Core spatial/block dễ học + Mahjong fantasy/collection/meta.
A15: Main risk | B15: Monetization proxy bị chi phối bởi vài outlier và revenue 0/missing.
A16: Next test | B16: A/B theme trên cùng core; đo FTUE, D1/D7, session, ads và IAP.
A19: Market | B19: Total downloads | D19: Market | E19: Positive growth share
A20: Block | B20: ='So sánh'!B5 -> 50634623 | D20: Block | E20: ='So sánh'!B11 -> 0.35555556
A21: Mahjong | B21: ='So sánh'!C5 -> 25960544 | D21: Mahjong | E21: ='So sánh'!C11 -> 0.57142857
A24: TOP OPPORTUNITY — CURRENT WEIGHTS
A25: Game | B25: =INDEX(Shortlist!B7:B79,MATCH(1,Shortlist!O7:O79,0)) -> Block Out! - Color Sort Puzzle
A26: Market | B26: =INDEX(Shortlist!A7:A79,MATCH(1,Shortlist!O7:O79,0)) -> Block
A27: Opportunity score | B27: =INDEX(Shortlist!N7:N79,MATCH(1,Shortlist!O7:O79,0)) -> 74.474668
A28: Research status | B28: =INDEX(Shortlist!P7:P79,MATCH(1,Shortlist!O7:O79,0)) -> Chưa review
A31: HOW TO USE
A32: 1 | B32: Đổi trọng số ở Shortlist!B2:E2 theo câu hỏi research.
A33: 2 | B33: Lọc Rank <= 15, sau đó review game và cập nhật status/notes.
A34: 3 | B34: Đọc So sánh để hiểu trade-off giữa scale, breadth và monetization.
A35: 4 | B35: Xem Phương pháp trước khi dùng kết luận cho product decision.

Sheet So sánh
A1: SO SÁNH THỊ TRƯỜNG: BLOCK vs MAHJONG
A2: Snapshot dựa trên 2 file nguồn; chỉ số PoP giữ nguyên định nghĩa của nguồn.
A3: Metric | B3: Block | C3: Mahjong | D3: Cách đọc
A4: Số game trong mẫu | B4: =COUNTA('Block Data'!A2:A50) -> 49 | C4: =COUNTA('Mahjong Data'!A2:A25) -> 24 | D4: Quy mô mẫu, không phải toàn thị trường
A5: Tổng downloads | B5: =SUM('Block Data'!C2:C50) -> 50634623 | C5: =SUM('Mahjong Data'!C2:C25) -> 25960544 | D5: Tín hiệu quy mô nhu cầu trong snapshot
A6: Downloads trung bình/game | B6: =AVERAGE('Block Data'!C2:C50) -> 1033359.7 | C6: =AVERAGE('Mahjong Data'!C2:C25) -> 1081689.3 | D6: Nhạy với game dẫn đầu
A7: Downloads trung vị/game | B7: =MEDIAN('Block Data'!C2:C50) -> 232263 | C7: =MEDIAN('Mahjong Data'!C2:C25) -> 395272 | D7: Đại diện game điển hình tốt hơn average
A8: Tổng revenue | B8: =SUM('Block Data'!F2:F50) -> 17308927 | C8: =SUM('Mahjong Data'!F2:F25) -> 978960.23 | D8: Cần thận trọng: số 0 có thể là thiếu dữ liệu
A9: Revenue / 1.000 downloads | B9: =SUM('Block Data'!F2:F50)/SUM('Block Data'!C2:C50)*1000 -> 341.83976 | C9: =SUM('Mahjong Data'!F2:F25)/SUM('Mahjong Data'!C2:C25)*1000 -> 37.709542 | D9: Proxy monetization, không phải ARPU
A10: Tăng trưởng downloads PoP có trọng số | B10: =SUM('Block Data'!D2:D50)/SUM('Block Data'!K2:K50) -> 0.0046775644 | C10: =SUM('Mahjong Data'!D2:D25)/SUM('Mahjong Data'!K2:K25) -> 0.04510079 | D10: Tổng thay đổi / tổng kỳ trước
A11: Tỷ lệ game tăng downloads | B11: =COUNTIF('Block Data'!E2:E50,">0")/COUNT('Block Data'!E2:E50) -> 0.35555556 | C11: =COUNTIF('Mahjong Data'!E2:E25,">0")/COUNT('Mahjong Data'!E2:E25) -> 0.57142857 | D11: Độ rộng của momentum
A12: Tỷ lệ Accelerating hoặc game mới | B12: =(COUNTIF('Block Data'!N2:N50,"Accelerating")+COUNTIF('Block Data'!N2:N50,"New / no prior"))/COUNTA('Block Data'!A2:A50) -> 0.28571429 | C12: =(COUNTIF('Mahjong Data'!N2:N25,"Accelerating")+COUNTIF('Mahjong Data'!N2:N25,"New / no prior"))/COUNTA('Mahjong Data'!A2:A25) -> 0.375 | D12: Game tăng >=20% hoặc chưa có kỳ trước
A13: Tập trung downloads Top 5 | B13: {=SUM(LARGE('Block Data'!C2:C50,{1,2,3,4,5}))/SUM('Block Data'!C2:C50)} -> 0.74739026 | C13: {=SUM(LARGE('Mahjong Data'!C2:C25,{1,2,3,4,5}))/SUM('Mahjong Data'!C2:C25)} -> 0.72269198 | D13: Càng cao càng phụ thuộc vài hit
A14: Game phát hành trong 365 ngày | B14: =COUNTIF('Block Data'!I2:I50,">="&TODAY()-365) -> 16 | C14: =COUNTIF('Mahjong Data'!I2:I25,">="&TODAY()-365) -> 10 | D14: Cường độ nguồn cung mới
A15: Game #1 theo downloads | B15: =INDEX('Block Data'!A2:A50,MATCH(MAX('Block Data'!C2:C50),'Block Data'!C2:C50,0)) -> Block Blast! | C15: =INDEX('Mahjong Data'!A2:A25,MATCH(MAX('Mahjong Data'!C2:C25),'Mahjong Data'!C2:C25,0)) -> Vita Mahjong | D15: Leader về reach
A16: Game #1 theo revenue | B16: =INDEX('Block Data'!A2:A50,MATCH(MAX('Block Data'!F2:F50),'Block Data'!F2:F50,0)) -> Block Out! - Color Sort Puzzle | C16: =INDEX('Mahjong Data'!A2:A25,MATCH(MAX('Mahjong Data'!F2:F25),'Mahjong Data'!F2:F25,0)) -> Mahjong Crush: Sorting Jam | D16: Leader về monetization
A19: RESEARCH TAKEAWAYS
A20: 1. Scale | B20: Block đạt 50,6M downloads; Mahjong đạt 26,0M. | D20: Block cho thấy demand lớn hơn trong mẫu.
A21: 2. Breadth of momentum | B21: 35,6% game Block có dữ liệu tăng trưởng là dương; Mahjong là 57,1%. | D21: Mahjong đang có momentum rộng hơn.
A22: 3. Monetization proxy | B22: Block ~341,8 revenue/1k DL; Mahjong ~37,7. | D22: Khoảng cách bị chi phối bởi vài game revenue rất lớn.
A23: 4. Market concentration | B23: Top 5 chiếm ~74,7% downloads Block và ~72,3% Mahjong. | D23: Cả hai đều là hit-driven market.
A24: 5. Hybrid hypothesis | B24: Dùng core spatial/block dễ hiểu + fantasy/collection Mahjong. | D24: Kết hợp scale của Block với momentum/theme của Mahjong.
A25: 6. Prototype test | B25: So sánh theme Mahjong với theme abstract trên cùng core loop. | D25: Theo dõi FTUE, D1/D7, session length, ads và IAP riêng.
A26: 7. Competitor focus | B26: Block Out, Color Block Jam, Mahjong Blast, Vita Mahjong, Mahjong Crush. | D26: Review store page, FTUE, fail loop, meta và monetization.
A27: Caveat | B27: Nguồn không nêu rõ quốc gia, store, kỳ đo, currency; revenue 0 có thể là missing. | D27: Không dùng workbook này như market size tuyệt đối.

Sheet Shortlist
A1: SHORTLIST & OPPORTUNITY SCORING
A2: Trọng số | B2: 0.35 | C2: 0.3 | D2: 0.25 | E2: 0.1 | F2: =SUM(B2:E2) -> 1
A3: Dimension | B3: Traction | C3: Momentum | D3: Monetization | E3: Recency | F3: Tổng trọng số
A5: Điểm 0–100. Growth được cap để giảm méo bởi game có base rất nhỏ; chỉnh trọng số B2:E2 để đổi lens.
A6: Market | B6: Game | C6: Publisher | D6: Downloads | E6: DL growth % | F6: Revenue | G6: Revenue growth % | H6: Release date | I6: Revenue / 1k DL | J6: Traction | K6: Momentum | L6: Monetization | M6: Recency | N6: Opportunity score | O6: Rank | P6: Research status | Q6: Notes
A7: ="Block" -> Block | B7: ='Block Data'!A2 -> Block Blast! | C7: ='Block Data'!B2 -> Hungry Studio | D7: ='Block Data'!C2 -> 18262736 | E7: =IF('Block Data'!E2="","",'Block Data'!E2) -> -0.041372 | F7: ='Block Data'!F2 -> 7082.69 | G7: =IF('Block Data'!H2="","",'Block Data'!H2) -> -0.337863 | H7: =IF('Block Data'!I2="","",'Block Data'!I2) -> 44654 | I7: ='Block Data'!M2 -> 0.38782196 | J7: =IFERROR(LOG10(D7+1)/LOG10(MAX($D$7:$D$79)+1)*100,0) -> 100 | K7: =IF(E7="",50,MAX(0,MIN(100,(E7+0.25)/1.25*100))) -> 16.69024 | L7: =IFERROR(IF(MAX($I$7:$I$79)=0,0,LOG10(I7+1)/LOG10(MAX($I$7:$I$79)+1)*100),0) -> 3.9126637 | M7: =IF(H7="",30,MAX(0,100-(TODAY()-H7)/1095*100)) -> 0 | N7: =SUMPRODUCT(J7:M7,$B$2:$E$2) -> 40.985238 | O7: =_xlfn.RANK.EQ(N7,$N$7:$N$79,0) -> 39 | P7: Chưa review
A8: ="Block" -> Block | B8: ='Block Data'!A3 -> Color Block: Combo Blast | C8: ='Block Data'!B3 -> Ivy Mobile | D8: ='Block Data'!C3 -> 7436099 | E8: =IF('Block Data'!E3="","",'Block Data'!E3) -> -0.027894 | F8: ='Block Data'!F3 -> 1543.22 | G8: =IF('Block Data'!H3="","",'Block Data'!H3) -> 0.767964 | H8: =IF('Block Data'!I3="","",'Block Data'!I3) -> 43572 | I8: ='Block Data'!M3 -> 0.20753086 | J8: =IFERROR(LOG10(D8+1)/LOG10(MAX($D$7:$D$79)+1)*100,0) -> 94.626219 | K8: =IF(E8="",50,MAX(0,MIN(100,(E8+0.25)/1.25*100))) -> 17.76848 | L8: =IFERROR(IF(MAX($I$7:$I$79)=0,0,LOG10(I8+1)/LOG10(MAX($I$7:$I$79)+1)*100),0) -> 2.2513301 | M8: =IF(H8="",30,MAX(0,100-(TODAY()-H8)/1095*100)) -> 0 | N8: =SUMPRODUCT(J8:M8,$B$2:$E$2) -> 39.012553 | O8: =_xlfn.RANK.EQ(N8,$N$7:$N$79,0) -> 46 | P8: Chưa review
A9: ="Block" -> Block | B9: ='Block Data'!A4 -> Block Out! - Color Sort Puzzle | C9: ='Block Data'!B4 -> Grand Games | D9: ='Block Data'!C4 -> 7252293 | E9: =IF('Block Data'!E4="","",'Block Data'!E4) -> 0.290037 | F9: ='Block Data'!F4 -> 9381506 | G9: =IF('Block Data'!H4="","",'Block Data'!H4) -> 0.030955 | H9: =IF('Block Data'!I4="","",'Block Data'!I4) -> 45930 | I9: ='Block Data'!M4 -> 1293.5917 | J9: =IFERROR(LOG10(D9+1)/LOG10(MAX($D$7:$D$79)+1)*100,0) -> 94.476529 | K9: =IF(E9="",50,MAX(0,MIN(100,(E9+0.25)/1.25*100))) -> 43.20296 | L9: =IFERROR(IF(MAX($I$7:$I$79)=0,0,LOG10(I9+1)/LOG10(MAX($I$7:$I$79)+1)*100),0) -> 85.550537 | M9: =IF(H9="",30,MAX(0,100-(TODAY()-H9)/1095*100)) -> 70.593607 | N9: =SUMPRODUCT(J9:M9,$B$2:$E$2) -> 74.474668 | O9: =_xlfn.RANK.EQ(N9,$N$7:$N$79,0) -> 1 | P9: Chưa review
A10: ="Block" -> Block | B10: ='Block Data'!A5 -> Block Crush! | C10: ='Block Data'!B5 -> Wonderful Studio | D10: ='Block Data'!C5 -> 3252846 | E10: =IF('Block Data'!E5="","",'Block Data'!E5) -> 0.407561 | F10: ='Block Data'!F5 -> 0 | G10: =IF('Block Data'!H5="","",'Block Data'!H5) | H10: =IF('Block Data'!I5="","",'Block Data'!I5) -> 44544 | I10: ='Block Data'!M5 -> 0 | J10: =IFERROR(LOG10(D10+1)/LOG10(MAX($D$7:$D$79)+1)*100,0) -> 89.681258 | K10: =IF(E10="",50,MAX(0,MIN(100,(E10+0.25)/1.25*100))) -> 52.60488 | L10: =IFERROR(IF(MAX($I$7:$I$79)=0,0,LOG10(I10+1)/LOG10(MAX($I$7:$I$79)+1)*100),0) -> 0 | M10: =IF(H10="",30,MAX(0,100-(TODAY()-H10)/1095*100)) -> 0 | N10: =SUMPRODUCT(J10:M10,$B$2:$E$2) -> 47.169904 | O10: =_xlfn.RANK.EQ(N10,$N$7:$N$79,0) -> 27 | P10: Chưa review
A11: ="Block" -> Block | B11: ='Block Data'!A6 -> Color Block Jam | C11: ='Block Data'!B6 -> Rollic Games | D11: ='Block Data'!C6 -> 1639850 | E11: =IF('Block Data'!E6="","",'Block Data'!E6) -> -0.376467 | F11: ='Block Data'!F6 -> 7119923.3 | G11: =IF('Block Data'!H6="","",'Block Data'!H6) -> -0.023352 | H11: =IF('Block Data'!I6="","",'Block Data'!I6) -> 45471 | I11: ='Block Data'!M6 -> 4341.8138 | J11: =IFERROR(LOG10(D11+1)/LOG10(MAX($D$7:$D$79)+1)*100,0) -> 85.584907 | K11: =IF(E11="",50,MAX(0,MIN(100,(E11+0.25)/1.25*100))) -> 0 | L11: =IFERROR(IF(MAX($I$7:$I$79)=0,0,LOG10(I11+1)/LOG10(MAX($I$7:$I$79)+1)*100),0) -> 100 | M11: =IF(H11="",30,MAX(0,100-(TODAY()-H11)/1095*100)) -> 28.675799 | N11: =SUMPRODUCT(J11:M11,$B$2:$E$2) -> 57.822297 | O11: =_xlfn.RANK.EQ(N11,$N$7:$N$79,0) -> 8 | P11: Chưa review
A12: ="Block" -> Block | B12: ='Block Data'!A7 -> Block Color Mania, Puzzle Game | C12: ='Block Data'!B7 -> Guru Puzzle Game | D12: ='Block Data'!C7 -> 1405074 | E12: =IF('Block Data'!E7="","",'Block Data'!E7) -> -0.178502 | F12: ='Block Data'!F7 -> 8434.13 | G12: =IF('Block Data'!H7="","",'Block Data'!H7) -> -0.079221 | H12: =IF('Block Data'!I7="","",'Block Data'!I7) -> 45986 | I12: ='Block Data'!M7 -> 6.0026233 | J12: =IFERROR(LOG10(D12+1)/LOG10(MAX($D$7:$D$79)+1)*100,0) -> 84.660797 | K12: =IF(E12="",50,MAX(0,MIN(100,(E12+0.25)/1.25*100))) -> 5.71984 | L12: =IFERROR(IF(MAX($I$7:$I$79)=0,0,LOG10(I12+1)/LOG10(MAX($I$7:$I$79)+1)*100),0) -> 23.235677 | M12: =IF(H12="",30,MAX(0,100-(TODAY()-H12)/1095*100)) -> 75.707763 | N12: =SUMPRODUCT(J12:M12,$B$2:$E$2) -> 44.726926 | O12: =_xlfn.RANK.EQ(N12,$N$7:$N$79,0) -> 32 | P12: Chưa review
A13: ="Block" -> Block | B13: ='Block Data'!A8 -> Block Puzzle Gem: Jewel Blast | C13: ='Block Data'!B8 -> Lynn Mobile Puzzle Games | D13: ='Block Data'!C8 -> 996806 | E13: =IF('Block Data'!E8="","",'Block Data'!E8) -> -0.121472 | F13: ='Block Data'!F8 -> 114.74 | G13: =IF('Block Data'!H8="","",'Block Data'!H8) -> -0.458697 | H13: =IF('Block Data'!I8="","",'Block Data'!I8) -> 43632 | I13: ='Block Data'!M8 -> 0.11510765 | J13: =IFERROR(LOG10(D13+1)/LOG10(MAX($D$7:$D$79)+1)*100,0) -> 82.60768 | K13: =IF(E13="",50,MAX(0,MIN(100,(E13+0.25)/1.25*100))) -> 10.28224 | L13: =IFERROR(IF(MAX($I$7:$I$79)=0,0,LOG10(I13+1)/LOG10(MAX($I$7:$I$79)+1)*100),0) -> 1.3007084 | M13: =IF(H13="",30,MAX(0,100-(TODAY()-H13)/1095*100)) -> 0 | N13: =SUMPRODUCT(J13:M13,$B$2:$E$2) -> 32.322537 | O13: =_xlfn.RANK.EQ(N13,$N$7:$N$79,0) -> 61 | P13: Chưa review
A14: ="Block" -> Block | B14: ='Block Data'!A9 -> Maze Escape: Rolling ball game | C14: ='Block Data'!B9 -> Fiogonia | D14: ='Block Data'!C9 -> 846191 | E14: =IF('Block Data'!E9="","",'Block Data'!E9) -> 52.969705 | F14: ='Block Data'!F9 -> 810.09 | G14: =IF('Block Data'!H9="","",'Block Data'!H9) -> 8.261347 | H14: =IF('Block Data'!I9="","",'Block Data'!I9) -> 45905 | I14: ='Block Data'!M9 -> 0.95733706 | J14: =IFERROR(LOG10(D14+1)/LOG10(MAX($D$7:$D$79)+1)*100,0) -> 81.627972 | K14: =IF(E14="",50,MAX(0,MIN(100,(E14+0.25)/1.25*100))) -> 100 | L14: =IFERROR(IF(MAX($I$7:$I$79)=0,0,LOG10(I14+1)/LOG10(MAX($I$7:$I$79)+1)*100),0) -> 8.017701 | M14: =IF(H14="",30,MAX(0,100-(TODAY()-H14)/1095*100)) -> 68.310502 | N14: =SUMPRODUCT(J14:M14,$B$2:$E$2) -> 67.405266 | O14: =_xlfn.RANK.EQ(N14,$N$7:$N$79,0) -> 3 | P14: Chưa review
A15: ="Block" -> Block | B15: ='Block Data'!A10 -> Block Puzzle | C15: ='Block Data'!B10 -> LinkDesks | D15: ='Block Data'!C10 -> 634004 | E15: =IF('Block Data'!E10="","",'Block Data'!E10) -> -0.067117 | F15: ='Block Data'!F10 -> 12473.96 | G15: =IF('Block Data'!H10="","",'Block Data'!H10) -> -0.193598 | H15: =IF('Block Data'!I10="","",'Block Data'!I10) -> 43238 | I15: ='Block Data'!M10 -> 19.674892 | J15: =IFERROR(LOG10(D15+1)/LOG10(MAX($D$7:$D$79)+1)*100,0) -> 79.901399 | K15: =IF(E15="",50,MAX(0,MIN(100,(E15+0.25)/1.25*100))) -> 14.63064 | L15: =IFERROR(IF(MAX($I$7:$I$79)=0,0,LOG10(I15+1)/LOG10(MAX($I$7:$I$79)+1)*100),0) -> 36.160692 | M15: =IF(H15="",30,MAX(0,100-(TODAY()-H15)/1095*100)) -> 0 | N15: =SUMPRODUCT(J15:M15,$B$2:$E$2) -> 41.394854 | O15: =_xlfn.RANK.EQ(N15,$N$7:$N$79,0) -> 36 | P15: Chưa review
A16: ="Block" -> Block | B16: ='Block Data'!A11 -> Woodoku Blast | C16: ='Block Data'!B11 -> Tripledot Studios | D16: ='Block Data'!C11 -> 537911 | E16: =IF('Block Data'!E11="","",'Block Data'!E11) -> 0.122444 | F16: ='Block Data'!F11 -> 3688.61 | G16: =IF('Block Data'!H11="","",'Block Data'!H11) -> 9.584854 | H16: =IF('Block Data'!I11="","",'Block Data'!I11) -> 45582 | I16: ='Block Data'!M11 -> 6.8572868 | J16: =IFERROR(LOG10(D16+1)/LOG10(MAX($D$7:$D$79)+1)*100,0) -> 78.918395 | K16: =IF(E16="",50,MAX(0,MIN(100,(E16+0.25)/1.25*100))) -> 29.79552 | L16: =IFERROR(IF(MAX($I$7:$I$79)=0,0,LOG10(I16+1)/LOG10(MAX($I$7:$I$79)+1)*100),0) -> 24.61047 | M16: =IF(H16="",30,MAX(0,100-(TODAY()-H16)/1095*100)) -> 38.812785 | N16: =SUMPRODUCT(J16:M16,$B$2:$E$2) -> 46.59399 | O16: =_xlfn.RANK.EQ(N16,$N$7:$N$79,0) -> 28 | P16: Chưa review
A17: ="Block" -> Block | B17: ='Block Data'!A12 -> Fusion Blocks - A Puzzle Game | C17: ='Block Data'!B12 -> Oogway Apps | D17: ='Block Data'!C12 -> 525347 | E17: =IF('Block Data'!E12="","",'Block Data'!E12) -> 0.504766 | F17: ='Block Data'!F12 -> 2845.68 | G17: =IF('Block Data'!H12="","",'Block Data'!H12) -> 0.119205 | H17: =IF('Block Data'!I12="","",'Block Data'!I12) -> 44728 | I17: ='Block Data'!M12 -> 5.4167626 | J17: =IFERROR(LOG10(D17+1)/LOG10(MAX($D$7:$D$79)+1)*100,0) -> 78.777046 | K17: =IF(E17="",50,MAX(0,MIN(100,(E17+0.25)/1.25*100))) -> 60.38128 | L17: =IFERROR(IF(MAX($I$7:$I$79)=0,0,LOG10(I17+1)/LOG10(MAX($I$7:$I$79)+1)*100),0) -> 22.192599 | M17: =IF(H17="",30,MAX(0,100-(TODAY()-H17)/1095*100)) -> 0 | N17: =SUMPRODUCT(J17:M17,$B$2:$E$2) -> 51.2345 | O17: =_xlfn.RANK.EQ(N17,$N$7:$N$79,0) -> 17 | P17: Chưa review
A18: ="Block" -> Block | B18: ='Block Data'!A13 -> Block Puzzle Classic | C18: ='Block Data'!B13 -> Sofish | D18: ='Block Data'!C13 -> 439916 | E18: =IF('Block Data'!E13="","",'Block Data'!E13) -> -0.238965 | F18: ='Block Data'!F13 -> 0 | G18: =IF('Block Data'!H13="","",'Block Data'!H13) | H18: =IF('Block Data'!I13="","",'Block Data'!I13) -> 45898 | I18: ='Block Data'!M13 -> 0 | J18: =IFERROR(LOG10(D18+1)/LOG10(MAX($D$7:$D$79)+1)*100,0) -> 77.715617 | K18: =IF(E18="",50,MAX(0,MIN(100,(E18+0.25)/1.25*100))) -> 0.8828 | L18: =IFERROR(IF(MAX($I$7:$I$79)=0,0,LOG10(I18+1)/LOG10(MAX($I$7:$I$79)+1)*100),0) -> 0 | M18: =IF(H18="",30,MAX(0,100-(TODAY()-H18)/1095*100)) -> 67.671233 | N18: =SUMPRODUCT(J18:M18,$B$2:$E$2) -> 34.232429 | O18: =_xlfn.RANK.EQ(N18,$N$7:$N$79,0) -> 57 | P18: Chưa review
... A55: ="Block" -> Block | B55: ='Block Data'!A50 -> Block Blast: Relaxing Puzzle | C55: ='Block Data'!B50 -> Digital Payment Tech | D55: ='Block Data'!C50 -> 107576 | E55: =IF('Block Data'!E50="","",'Block Data'!E50) -> 51.450512 | F55: ='Block Data'!F50 -> 0 | G55: =IF('Block Data'!H50="","",'Block Data'!H50) | H55: =IF('Block Data'!I50="","",'Block Data'!I50) -> 46186 | I55: ='Block Data'!M50 -> 0 | J55: =IFERROR(LOG10(D55+1)/LOG10(MAX($D$7:$D$79)+1)*100,0) -> 69.292485 | K55: =IF(E55="",50,MAX(0,MIN(100,(E55+0.25)/1.25*100))) -> 100 | L55: =IFERROR(IF(MAX($I$7:$I$79)=0,0,LOG10(I55+1)/LOG10(MAX($I$7:$I$79)+1)*100),0) -> 0 | M55: =IF(H55="",30,MAX(0,100-(TODAY()-H55)/1095*100)) -> 93.972603 | N55: =SUMPRODUCT(J55:M55,$B$2:$E$2) -> 63.64963 | O55: =_xlfn.RANK.EQ(N55,$N$7:$N$79,0) -> 6 | P55: Chưa review
A56: ="Mahjong" -> Mahjong | B56: ='Mahjong Data'!A2 -> Vita Mahjong | C56: ='Mahjong Data'!B2 -> Learnings | D56: ='Mahjong Data'!C2 -> 9440900 | E56: =IF('Mahjong Data'!E2="","",'Mahjong Data'!E2) -> -0.120104 | F56: ='Mahjong Data'!F2 -> 158565.75 | G56: =IF('Mahjong Data'!H2="","",'Mahjong Data'!H2) -> 0.035592 | H56: =IF('Mahjong Data'!I2="","",'Mahjong Data'!I2) -> 45261 | I56: ='Mahjong Data'!M2 -> 16.795618 | J56: =IFERROR(LOG10(D56+1)/LOG10(MAX($D$7:$D$79)+1)*100,0) -> 96.053848 | K56: =IF(E56="",50,MAX(0,MIN(100,(E56+0.25)/1.25*100))) -> 10.39168 | L56: =IFERROR(IF(MAX($I$7:$I$79)=0,0,LOG10(I56+1)/LOG10(MAX($I$7:$I$79)+1)*100),0) -> 34.370305 | M56: =IF(H56="",30,MAX(0,100-(TODAY()-H56)/1095*100)) -> 9.4977169 | N56: =SUMPRODUCT(J56:M56,$B$2:$E$2) -> 46.278699 | O56: =_xlfn.RANK.EQ(N56,$N$7:$N$79,0) -> 29 | P56: Chưa review
A57: ="Mahjong" -> Mahjong | B57: ='Mahjong Data'!A3 -> Mahjong Blast | C57: ='Mahjong Data'!B3 -> Nebula Studio | D57: ='Mahjong Data'!C3 -> 5065843 | E57: =IF('Mahjong Data'!E3="","",'Mahjong Data'!E3) -> 0.445425 | F57: ='Mahjong Data'!F3 -> 2252.46 | G57: =IF('Mahjong Data'!H3="","",'Mahjong Data'!H3) -> 4.605086 | H57: =IF('Mahjong Data'!I3="","",'Mahjong Data'!I3) -> 45831 | I57: ='Mahjong Data'!M3 -> 0.44463676 | J57: =IFERROR(LOG10(D57+1)/LOG10(MAX($D$7:$D$79)+1)*100,0) -> 92.330662 | K57: =IF(E57="",50,MAX(0,MIN(100,(E57+0.25)/1.25*100))) -> 55.634 | L57: =IFERROR(IF(MAX($I$7:$I$79)=0,0,LOG10(I57+1)/LOG10(MAX($I$7:$I$79)+1)*100),0) -> 4.3916632 | M57: =IF(H57="",30,MAX(0,100-(TODAY()-H57)/1095*100)) -> 61.552511 | N57: =SUMPRODUCT(J57:M57,$B$2:$E$2) -> 56.259099 | O57: =_xlfn.RANK.EQ(N57,$N$7:$N$79,0) -> 12 | P57: Chưa review
A58: ="Mahjong" -> Mahjong | B58: ='Mahjong Data'!A4 -> Mahjong Master: Daily Match | C58: ='Mahjong Data'!B4 -> Pandas of Caribbean | D58: ='Mahjong Data'!C4 -> 2347780 | E58: =IF('Mahjong Data'!E4="","",'Mahjong Data'!E4) -> 0.36778 | F58: ='Mahjong Data'!F4 -> 326.39 | G58: =IF('Mahjong Data'!H4="","",'Mahjong Data'!H4) -> 1.240612 | H58: =IF('Mahjong Data'!I4="","",'Mahjong Data'!I4) -> 46044 | I58: ='Mahjong Data'!M4 -> 0.13902069 | J58: =IFERROR(LOG10(D58+1)/LOG10(MAX($D$7:$D$79)+1)*100,0) -> 87.731182 | K58: =IF(E58="",50,MAX(0,MIN(100,(E58+0.25)/1.25*100))) -> 49.4224 | L58: =IFERROR(IF(MAX($I$7:$I$79)=0,0,LOG10(I58+1)/LOG10(MAX($I$7:$I$79)+1)*100),0) -> 1.5540178 | M58: =IF(H58="",30,MAX(0,100-(TODAY()-H58)/1095*100)) -> 81.004566 | N58: =SUMPRODUCT(J58:M58,$B$2:$E$2) -> 54.021595 | O58: =_xlfn.RANK.EQ(N58,$N$7:$N$79,0) -> 13 | P58: Chưa review
A59: ="Mahjong" -> Mahjong | B59: ='Mahjong Data'!A5 -> SoEasy Mahjong: Solitaire | C59: ='Mahjong Data'!B5 -> Sofish | D59: ='Mahjong Data'!C5 -> 1166304 | E59: =IF('Mahjong Data'!E5="","",'Mahjong Data'!E5) -> -0.350778 | F59: ='Mahjong Data'!F5 -> 0 | G59: =IF('Mahjong Data'!H5="","",'Mahjong Data'!H5) | H59: =IF('Mahjong Data'!I5="","",'Mahjong Data'!I5) -> 46129 | I59: ='Mahjong Data'!M5 -> 0 | J59: =IFERROR(LOG10(D59+1)/LOG10(MAX($D$7:$D$79)+1)*100,0) -> 83.546886 | K59: =IF(E59="",50,MAX(0,MIN(100,(E59+0.25)/1.25*100))) -> 0 | L59: =IFERROR(IF(MAX($I$7:$I$79)=0,0,LOG10(I59+1)/LOG10(MAX($I$7:$I$79)+1)*100),0) -> 0 | M59: =IF(H59="",30,MAX(0,100-(TODAY()-H59)/1095*100)) -> 88.767123 | N59: =SUMPRODUCT(J59:M59,$B$2:$E$2) -> 38.118122 | O59: =_xlfn.RANK.EQ(N59,$N$7:$N$79,0) -> 50 | P59: Chưa review
A60: ="Mahjong" -> Mahjong | B60: ='Mahjong Data'!A6 -> Tile Mahjong Classic | C60: ='Mahjong Data'!B6 -> Sofish | D60: ='Mahjong Data'!C6 -> 740650 | E60: =IF('Mahjong Data'!E6="","",'Mahjong Data'!E6) -> -0.30037 | F60: ='Mahjong Data'!F6 -> 3497.24 | G60: =IF('Mahjong Data'!H6="","",'Mahjong Data'!H6) -> -0.177641 | H60: =IF('Mahjong Data'!I6="","",'Mahjong Data'!I6) -> 46070 | I60: ='Mahjong Data'!M6 -> 4.7218524 | J60: =IFERROR(LOG10(D60+1)/LOG10(MAX($D$7:$D$79)+1)*100,0) -> 80.831238 | K60: =IF(E60="",50,MAX(0,MIN(100,(E60+0.25)/1.25*100))) -> 0 | L60: =IFERROR(IF(MAX($I$7:$I$79)=0,0,LOG10(I60+1)/LOG10(MAX($I$7:$I$79)+1)*100),0) -> 20.824197 | M60: =IF(H60="",30,MAX(0,100-(TODAY()-H60)/1095*100)) -> 83.378995 | N60: =SUMPRODUCT(J60:M60,$B$2:$E$2) -> 41.834882 | O60: =_xlfn.RANK.EQ(N60,$N$7:$N$79,0) -> 35 | P60: Chưa review
A61: ="Mahjong" -> Mahjong | B61: ='Mahjong Data'!A7 -> Mahjong Traveler! | C61: ='Mahjong Data'!B7 -> Kuyisi Digital | D61: ='Mahjong Data'!C7 -> 640526 | E61: =IF('Mahjong Data'!E7="","",'Mahjong Data'!E7) -> 0.167271 | F61: ='Mahjong Data'!F7 -> 0 | G61: =IF('Mahjong Data'!H7="","",'Mahjong Data'!H7) | H61: =IF('Mahjong Data'!I7="","",'Mahjong Data'!I7) | I61: ='Mahjong Data'!M7 -> 0 | J61: =IFERROR(LOG10(D61+1)/LOG10(MAX($D$7:$D$79)+1)*100,0) -> 79.962608 | K61: =IF(E61="",50,MAX(0,MIN(100,(E61+0.25)/1.25*100))) -> 33.38168 | L61: =IFERROR(IF(MAX($I$7:$I$79)=0,0,LOG10(I61+1)/LOG10(MAX($I$7:$I$79)+1)*100),0) -> 0 | M61: =IF(H61="",30,MAX(0,100-(TODAY()-H61)/1095*100)) -> 30 | N61: =SUMPRODUCT(J61:M61,$B$2:$E$2) -> 41.001417 | O61: =_xlfn.RANK.EQ(N61,$N$7:$N$79,0) -> 38 | P61: Chưa review
A62: ="Mahjong" -> Mahjong | B62: ='Mahjong Data'!A8 -> Mahjong-Match Puzzle Games | C62: ='Mahjong Data'!B8 -> GameTree | D62: ='Mahjong Data'!C8 -> 554079 | E62: =IF('Mahjong Data'!E8="","",'Mahjong Data'!E8) -> 0.285614 | F62: ='Mahjong Data'!F8 -> 177.1 | G62: =IF('Mahjong Data'!H8="","",'Mahjong Data'!H8) -> -0.119519 | H62: =IF('Mahjong Data'!I8="","",'Mahjong Data'!I8) -> 44691 | I62: ='Mahjong Data'!M8 -> 0.31962951 | J62: =IFERROR(LOG10(D62+1)/LOG10(MAX($D$7:$D$79)+1)*100,0) -> 79.095509 | K62: =IF(E62="",50,MAX(0,MIN(100,(E62+0.25)/1.25*100))) -> 42.84912 | L62: =IFERROR(IF(MAX($I$7:$I$79)=0,0,LOG10(I62+1)/LOG10(MAX($I$7:$I$79)+1)*100),0) -> 3.3111488 | M62: =IF(H62="",30,MAX(0,100-(TODAY()-H62)/1095*100)) -> 0 | N62: =SUMPRODUCT(J62:M62,$B$2:$E$2) -> 41.365951 | O62: =_xlfn.RANK.EQ(N62,$N$7:$N$79,0) -> 37 | P62: Chưa review
A63: ="Mahjong" -> Mahjong | B63: ='Mahjong Data'!A9 -> Mahjongscapes - Tile Match | C63: ='Mahjong Data'!B9 -> PARTYPOP | D63: ='Mahjong Data'!C9 -> 541008 | E63: =IF('Mahjong Data'!E9="","",'Mahjong Data'!E9) -> -0.099221 | F63: ='Mahjong Data'!F9 -> 694.08 | G63: =IF('Mahjong Data'!H9="","",'Mahjong Data'!H9) -> 0.284358 | H63: =IF('Mahjong Data'!I9="","",'Mahjong Data'!I9) -> 45672 | I63: ='Mahjong Data'!M9 -> 1.2829385 | J63: =IFERROR(LOG10(D63+1)/LOG10(MAX($D$7:$D$79)+1)*100,0) -> 78.95273 | K63: =IF(E63="",50,MAX(0,MIN(100,(E63+0.25)/1.25*100))) -> 12.06232 | L63: =IFERROR(IF(MAX($I$7:$I$79)=0,0,LOG10(I63+1)/LOG10(MAX($I$7:$I$79)+1)*100),0) -> 9.8547763 | M63: =IF(H63="",30,MAX(0,100-(TODAY()-H63)/1095*100)) -> 47.031963 | N63: =SUMPRODUCT(J63:M63,$B$2:$E$2) -> 38.419042 | O63: =_xlfn.RANK.EQ(N63,$N$7:$N$79,0) -> 49 | P63: Chưa review
A64: ="Mahjong" -> Mahjong | B64: ='Mahjong Data'!A10 -> Mahjong Cash Link | C64: ='Mahjong Data'!B10 -> Jva TTC | D64: ='Mahjong Data'!C10 -> 500239 | E64: =IF('Mahjong Data'!E10="","",'Mahjong Data'!E10) | F64: ='Mahjong Data'!F10 -> 0 | G64: =IF('Mahjong Data'!H10="","",'Mahjong Data'!H10) | H64: =IF('Mahjong Data'!I10="","",'Mahjong Data'!I10) -> 46211 | I64: ='Mahjong Data'!M10 -> 0 | J64: =IFERROR(LOG10(D64+1)/LOG10(MAX($D$7:$D$79)+1)*100,0) -> 78.484152 | K64: =IF(E64="",50,MAX(0,MIN(100,(E64+0.25)/1.25*100))) -> 50 | L64: =IFERROR(IF(MAX($I$7:$I$79)=0,0,LOG10(I64+1)/LOG10(MAX($I$7:$I$79)+1)*100),0) -> 0 | M64: =IF(H64="",30,MAX(0,100-(TODAY()-H64)/1095*100)) -> 96.255708 | N64: =SUMPRODUCT(J64:M64,$B$2:$E$2) -> 52.095024 | O64: =_xlfn.RANK.EQ(N64,$N$7:$N$79,0) -> 15 | P64: Chưa review
A65: ="Mahjong" -> Mahjong | B65: ='Mahjong Data'!A11 -> Mahjong Mingle | C65: ='Mahjong Data'!B11 -> Playful Bytes | D65: ='Mahjong Data'!C11 -> 493628 | E65: =IF('Mahjong Data'!E11="","",'Mahjong Data'!E11) -> 0.40979 | F65: ='Mahjong Data'!F11 -> 0 | G65: =IF('Mahjong Data'!H11="","",'Mahjong Data'!H11) | H65: =IF('Mahjong Data'!I11="","",'Mahjong Data'!I11) -> 45646 | I65: ='Mahjong Data'!M11 -> 0 | J65: =IFERROR(LOG10(D65+1)/LOG10(MAX($D$7:$D$79)+1)*100,0) -> 78.404586 | K65: =IF(E65="",50,MAX(0,MIN(100,(E65+0.25)/1.25*100))) -> 52.7832 | L65: =IFERROR(IF(MAX($I$7:$I$79)=0,0,LOG10(I65+1)/LOG10(MAX($I$7:$I$79)+1)*100),0) -> 0 | M65: =IF(H65="",30,MAX(0,100-(TODAY()-H65)/1095*100)) -> 44.657534 | N65: =SUMPRODUCT(J65:M65,$B$2:$E$2) -> 47.742319 | O65: =_xlfn.RANK.EQ(N65,$N$7:$N$79,0) -> 26 | P65: Chưa review
A66: ="Mahjong" -> Mahjong | B66: ='Mahjong Data'!A12 -> Mahjong Slide: Zen | C66: ='Mahjong Data'!B12 -> Playful Bytes | D66: ='Mahjong Data'!C12 -> 459472 | E66: =IF('Mahjong Data'!E12="","",'Mahjong Data'!E12) -> 0.219185 | F66: ='Mahjong Data'!F12 -> 0 | G66: =IF('Mahjong Data'!H12="","",'Mahjong Data'!H12) | H66: =IF('Mahjong Data'!I12="","",'Mahjong Data'!I12) -> 45908 | I66: ='Mahjong Data'!M12 -> 0 | J66: =IFERROR(LOG10(D66+1)/LOG10(MAX($D$7:$D$79)+1)*100,0) -> 77.975744 | K66: =IF(E66="",50,MAX(0,MIN(100,(E66+0.25)/1.25*100))) -> 37.5348 | L66: =IFERROR(IF(MAX($I$7:$I$79)=0,0,LOG10(I66+1)/LOG10(MAX($I$7:$I$79)+1)*100),0) -> 0 | M66: =IF(H66="",30,MAX(0,100-(TODAY()-H66)/1095*100)) -> 68.584475 | N66: =SUMPRODUCT(J66:M66,$B$2:$E$2) -> 45.410398 | O66: =_xlfn.RANK.EQ(N66,$N$7:$N$79,0) -> 30 | P66: Chưa review
A67: ="Mahjong" -> Mahjong | B67: ='Mahjong Data'!A13 -> Shanghai Mahjongg | C67: ='Mahjong Data'!B13 -> UniRise Digital | D67: ='Mahjong Data'!C13 -> 403181 | E67: =IF('Mahjong Data'!E13="","",'Mahjong Data'!E13) -> -0.193488 | F67: ='Mahjong Data'!F13 -> 1429.25 | G67: =IF('Mahjong Data'!H13="","",'Mahjong Data'!H13) -> -0.141653 | H67: =IF('Mahjong Data'!I13="","",'Mahjong Data'!I13) -> 45478 | I67: ='Mahjong Data'!M13 -> 3.5449339 | J67: =IFERROR(LOG10(D67+1)/LOG10(MAX($D$7:$D$79)+1)*100,0) -> 77.19411 | K67: =IF(E67="",50,MAX(0,MIN(100,(E67+0.25)/1.25*100))) -> 4.52096 | L67: =IFERROR(IF(MAX($I$7:$I$79)=0,0,LOG10(I67+1)/LOG10(MAX($I$7:$I$79)+1)*100),0) -> 18.075012 | M67: =IF(H67="",30,MAX(0,100-(TODAY()-H67)/1095*100)) -> 29.315068 | N67: =SUMPRODUCT(J67:M67,$B$2:$E$2) -> 35.824486 | O67: =_xlfn.RANK.EQ(N67,$N$7:$N$79,0) -> 53 | P67: Chưa review
... A79: ="Mahjong" -> Mahjong | B79: ='Mahjong Data'!A25 -> Zen Garden Mahjong | C79: ='Mahjong Data'!B25 -> AMG DevBM | D79: ='Mahjong Data'!C25 -> 164028 | E79: =IF('Mahjong Data'!E25="","",'Mahjong Data'!E25) -> 5.891354 | F79: ='Mahjong Data'!F25 -> 0 | G79: =IF('Mahjong Data'!H25="","",'Mahjong Data'!H25) | H79: =IF('Mahjong Data'!I25="","",'Mahjong Data'!I25) -> 46178 | I79: ='Mahjong Data'!M25 -> 0 | J79: =IFERROR(LOG10(D79+1)/LOG10(MAX($D$7:$D$79)+1)*100,0) -> 71.815373 | K79: =IF(E79="",50,MAX(0,MIN(100,(E79+0.25)/1.25*100))) -> 100 | L79: =IFERROR(IF(MAX($I$7:$I$79)=0,0,LOG10(I79+1)/LOG10(MAX($I$7:$I$79)+1)*100),0) -> 0 | M79: =IF(H79="",30,MAX(0,100-(TODAY()-H79)/1095*100)) -> 93.242009 | N79: =SUMPRODUCT(J79:M79,$B$2:$E$2) -> 64.459582 | O79: =_xlfn.RANK.EQ(N79,$N$7:$N$79,0) -> 5 | P79: Chưa review

Sheet Block Data
A1: Game | B1: Publisher | C1: Downloads | D1: DL PoP Δ | E1: DL PoP % | F1: Revenue | G1: Revenue PoP Δ | H1: Revenue PoP % | I1: Release date | J1: Release age | K1: Prior downloads | L1: Prior revenue | M1: Revenue / 1k DL | N1: Momentum tag | O1: Source file
A2: Block Blast! | B2: Hungry Studio | C2: 18262736 | D2: -788177 | E2: -0.041372 | F2: 7082.69 | G2: -3614.02 | H2: -0.337863 | I2: 44654 | J2: > 3 years | K2: =C2-D2 -> 19050913 | L2: =F2-G2 -> 10696.71 | M2: =IF(C2=0,"",F2/C2*1000) -> 0.38782196 | N2: =IF(ISBLANK(E2),"New / no prior",IF(E2>=0.2,"Accelerating",IF(E2>0,"Growing",IF(E2>=-0.1,"Stable","Declining")))) -> Stable | O2: Block market.txt
A3: Color Block: Combo Blast | B3: Ivy Mobile | C3: 7436099 | D3: -213371 | E3: -0.027894 | F3: 1543.22 | G3: 670.34 | H3: 0.767964 | I3: 43572 | J3: > 3 years | K3: =C3-D3 -> 7649470 | L3: =F3-G3 -> 872.88 | M3: =IF(C3=0,"",F3/C3*1000) -> 0.20753086 | N3: =IF(ISBLANK(E3),"New / no prior",IF(E3>=0.2,"Accelerating",IF(E3>0,"Growing",IF(E3>=-0.1,"Stable","Declining")))) -> Stable | O3: Block market.txt
A4: Block Out! - Color Sort Puzzle | B4: Grand Games | C4: 7252293 | D4: 1630522 | E4: 0.290037 | F4: 9381506 | G4: 281683.94 | H4: 0.030955 | I4: 45930 | J4: ~ 1 year | K4: =C4-D4 -> 5621771 | L4: =F4-G4 -> 9099822.1 | M4: =IF(C4=0,"",F4/C4*1000) -> 1293.5917 | N4: =IF(ISBLANK(E4),"New / no prior",IF(E4>=0.2,"Accelerating",IF(E4>0,"Growing",IF(E4>=-0.1,"Stable","Declining")))) -> Accelerating | O4: Block market.txt
A5: Block Crush! | B5: Wonderful Studio | C5: 3252846 | D5: 941866 | E5: 0.407561 | F5: 0 | G5: 0 | I5: 44544 | J5: > 3 years | K5: =C5-D5 -> 2310980 | L5: =F5-G5 -> 0 | M5: =IF(C5=0,"",F5/C5*1000) -> 0 | N5: =IF(ISBLANK(E5),"New / no prior",IF(E5>=0.2,"Accelerating",IF(E5>0,"Growing",IF(E5>=-0.1,"Stable","Declining")))) -> Accelerating | O5: Block market.txt
A6: Color Block Jam | B6: Rollic Games | C6: 1639850 | D6: -990082 | E6: -0.376467 | F6: 7119923.3 | G6: -170243.28 | H6: -0.023352 | I6: 45471 | J6: ~ 2 years | K6: =C6-D6 -> 2629932 | L6: =F6-G6 -> 7290166.6 | M6: =IF(C6=0,"",F6/C6*1000) -> 4341.8138 | N6: =IF(ISBLANK(E6),"New / no prior",IF(E6>=0.2,"Accelerating",IF(E6>0,"Growing",IF(E6>=-0.1,"Stable","Declining")))) -> Declining | O6: Block market.txt
A7: Block Color Mania, Puzzle Game | B7: Guru Puzzle Game | C7: 1405074 | D7: -305307 | E7: -0.178502 | F7: 8434.13 | G7: -725.65 | H7: -0.079221 | I7: 45986 | J7: ~ 1 year | K7: =C7-D7 -> 1710381 | L7: =F7-G7 -> 9159.78 | M7: =IF(C7=0,"",F7/C7*1000) -> 6.0026233 | N7: =IF(ISBLANK(E7),"New / no prior",IF(E7>=0.2,"Accelerating",IF(E7>0,"Growing",IF(E7>=-0.1,"Stable","Declining")))) -> Declining | O7: Block market.txt
A8: Block Puzzle Gem: Jewel Blast | B8: Lynn Mobile Puzzle Games | C8: 996806 | D8: -137826 | E8: -0.121472 | F8: 114.74 | G8: -97.23 | H8: -0.458697 | I8: 43632 | J8: > 3 years | K8: =C8-D8 -> 1134632 | L8: =F8-G8 -> 211.97 | M8: =IF(C8=0,"",F8/C8*1000) -> 0.11510765 | N8: =IF(ISBLANK(E8),"New / no prior",IF(E8>=0.2,"Accelerating",IF(E8>0,"Growing",IF(E8>=-0.1,"Stable","Declining")))) -> Declining | O8: Block market.txt
A9: Maze Escape: Rolling ball game | B9: Fiogonia | C9: 846191 | D9: 830512 | E9: 52.969705 | F9: 810.09 | G9: 722.62 | H9: 8.261347 | I9: 45905 | J9: ~ 1 year | K9: =C9-D9 -> 15679 | L9: =F9-G9 -> 87.47 | M9: =IF(C9=0,"",F9/C9*1000) -> 0.95733706 | N9: =IF(ISBLANK(E9),"New / no prior",IF(E9>=0.2,"Accelerating",IF(E9>0,"Growing",IF(E9>=-0.1,"Stable","Declining")))) -> Accelerating | O9: Block market.txt
A10: Block Puzzle | B10: LinkDesks | C10: 634004 | D10: -45614 | E10: -0.067117 | F10: 12473.96 | G10: -2994.7 | H10: -0.193598 | I10: 43238 | J10: > 3 years | K10: =C10-D10 -> 679618 | L10: =F10-G10 -> 15468.66 | M10: =IF(C10=0,"",F10/C10*1000) -> 19.674892 | N10: =IF(ISBLANK(E10),"New / no prior",IF(E10>=0.2,"Accelerating",IF(E10>0,"Growing",IF(E10>=-0.1,"Stable","Declining")))) -> Stable | O10: Block market.txt
A11: Woodoku Blast | B11: Tripledot Studios | C11: 537911 | D11: 58679 | E11: 0.122444 | F11: 3688.61 | G11: 3340.13 | H11: 9.584854 | I11: 45582 | J11: ~ 2 years | K11: =C11-D11 -> 479232 | L11: =F11-G11 -> 348.48 | M11: =IF(C11=0,"",F11/C11*1000) -> 6.8572868 | N11: =IF(ISBLANK(E11),"New / no prior",IF(E11>=0.2,"Accelerating",IF(E11>0,"Growing",IF(E11>=-0.1,"Stable","Declining")))) -> Growing | O11: Block market.txt
A12: Fusion Blocks - A Puzzle Game | B12: Oogway Apps | C12: 525347 | D12: 176225 | E12: 0.504766 | F12: 2845.68 | G12: 303.09 | H12: 0.119205 | I12: 44728 | J12: > 3 years | K12: =C12-D12 -> 349122 | L12: =F12-G12 -> 2542.59 | M12: =IF(C12=0,"",F12/C12*1000) -> 5.4167626 | N12: =IF(ISBLANK(E12),"New / no prior",IF(E12>=0.2,"Accelerating",IF(E12>0,"Growing",IF(E12>=-0.1,"Stable","Declining")))) -> Accelerating | O12: Block market.txt
A13: Block Puzzle Classic | B13: Sofish | C13: 439916 | D13: -138134 | E13: -0.238965 | F13: 0 | G13: 0 | I13: 45898 | J13: ~ 1 year | K13: =C13-D13 -> 578050 | L13: =F13-G13 -> 0 | M13: =IF(C13=0,"",F13/C13*1000) -> 0 | N13: =IF(ISBLANK(E13),"New / no prior",IF(E13>=0.2,"Accelerating",IF(E13>0,"Growing",IF(E13>=-0.1,"Stable","Declining")))) -> Declining | O13: Block market.txt
A14: Block Blitz: Puzzle Adventure | B14: Bluetile Games | C14: 376281 | D14: -140812 | E14: -0.272315 | F14: 0 | G14: 0 | I14: 46000 | J14: ~ 6 months | K14: =C14-D14 -> 517093 | L14: =F14-G14 -> 0 | M14: =IF(C14=0,"",F14/C14*1000) -> 0 | N14: =IF(ISBLANK(E14),"New / no prior",IF(E14>=0.2,"Accelerating",IF(E14>0,"Growing",IF(E14>=-0.1,"Stable","Declining")))) -> Declining | O14: Block market.txt
A15: Color Block Run - Puzzle Game | B15: Play2Ever Games | C15: 373039 | D15: -36777 | E15: -0.08974 | F15: 309030.47 | G15: 803.93 | H15: 0.002608 | I15: 45851 | J15: ~ 1 year | K15: =C15-D15 -> 409816 | L15: =F15-G15 -> 308226.54 | M15: =IF(C15=0,"",F15/C15*1000) -> 828.4133 | N15: =IF(ISBLANK(E15),"New / no prior",IF(E15>=0.2,"Accelerating",IF(E15>0,"Growing",IF(E15>=-0.1,"Stable","Declining")))) -> Stable | O15: Block market.txt
A16: Block Puzzle Wood Blast | B16: Wood Puzzle Sudoku Games | C16: 352497 | D16: -1951 | E16: -0.005504 | F16: 295.32 | G16: -50.02 | H16: -0.144843 | I16: 44102 | J16: > 3 years | K16: =C16-D16 -> 354448 | L16: =F16-G16 -> 345.34 | M16: =IF(C16=0,"",F16/C16*1000) -> 0.83779436 | N16: =IF(ISBLANK(E16),"New / no prior",IF(E16>=0.2,"Accelerating",IF(E16>0,"Growing",IF(E16>=-0.1,"Stable","Declining")))) -> Stable | O16: Block market.txt
A17: Block-Tok: Puzzle Game | B17: NewPubCo | C17: 347438 | D17: -26233 | E17: -0.070203 | F17: 0 | G17: 0 | I17: 45183 | J17: ~ 3 years | K17: =C17-D17 -> 373671 | L17: =F17-G17 -> 0 | M17: =IF(C17=0,"",F17/C17*1000) -> 0 | N17: =IF(ISBLANK(E17),"New / no prior",IF(E17>=0.2,"Accelerating",IF(E17>0,"Growing",IF(E17>=-0.1,"Stable","Declining")))) -> Stable | O17: Block market.txt
A18: Puzzle Game | B18: Block Puzzle Games 2018 | C18: 314663 | D18: -56633 | E18: -0.152528 | F18: 0 | G18: 0 | I18: 43622 | J18: > 3 years | K18: =C18-D18 -> 371296 | L18: =F18-G18 -> 0 | M18: =IF(C18=0,"",F18/C18*1000) -> 0 | N18: =IF(ISBLANK(E18),"New / no prior",IF(E18>=0.2,"Accelerating",IF(E18>0,"Growing",IF(E18>=-0.1,"Stable","Declining")))) -> Declining | O18: Block market.txt
A19: Block Blast Puzzle Mania | B19: Bibota | C19: 292250 | D19: -198287 | E19: -0.404224 | F19: 4.98 | G19: -2.98 | H19: -0.374372 | I19: 46007 | J19: ~ 6 months | K19: =C19-D19 -> 490537 | L19: =F19-G19 -> 7.96 | M19: =IF(C19=0,"",F19/C19*1000) -> 0.017040205 | N19: =IF(ISBLANK(E19),"New / no prior",IF(E19>=0.2,"Accelerating",IF(E19>0,"Growing",IF(E19>=-0.1,"Stable","Declining")))) -> Declining | O19: Block market.txt
A20: Block Puzzle | B20: Jinbing Wang | C20: 275351 | D20: 19161 | E20: 0.074792 | F20: 0 | G20: 0 | I20: 42739 | J20: > 3 years | K20: =C20-D20 -> 256190 | L20: =F20-G20 -> 0 | M20: =IF(C20=0,"",F20/C20*1000) -> 0 | N20: =IF(ISBLANK(E20),"New / no prior",IF(E20>=0.2,"Accelerating",IF(E20>0,"Growing",IF(E20>=-0.1,"Stable","Declining")))) -> Growing | O20: Block market.txt
A21: Block Buster - No Timer | B21: Lion Studios | C21: 266660 | D21: -32278 | E21: -0.107976 | F21: 305918.81 | G21: 89505.31 | H21: 0.413585 | I21: 45801 | J21: ~ 1 year | K21: =C21-D21 -> 298938 | L21: =F21-G21 -> 216413.5 | M21: =IF(C21=0,"",F21/C21*1000) -> 1147.2242 | N21: =IF(ISBLANK(E21),"New / no prior",IF(E21>=0.2,"Accelerating",IF(E21>0,"Growing",IF(E21>=-0.1,"Stable","Declining")))) -> Declining | O21: Block market.txt
A22: Block Blitz: Gems Puzzle | B22: Hypergames | C22: 254220 | D22: 7609 | E22: 0.030854 | F22: 1889.16 | G22: -255.54 | H22: -0.11915 | I22: 45629 | J22: ~ 2 years | K22: =C22-D22 -> 246611 | L22: =F22-G22 -> 2144.7 | M22: =IF(C22=0,"",F22/C22*1000) -> 7.4312013 | N22: =IF(ISBLANK(E22),"New / no prior",IF(E22>=0.2,"Accelerating",IF(E22>0,"Growing",IF(E22>=-0.1,"Stable","Declining")))) -> Growing | O22: Block market.txt
A23: Block Mania: Block Pop Blast | B23: Devio Studio | C23: 251806 | D23: 251806 | F23: 0 | G23: 0 | I23: 46204 | J23: ~ 1 month | K23: =C23-D23 -> 0 | L23: =F23-G23 -> 0 | M23: =IF(C23=0,"",F23/C23*1000) -> 0 | N23: =IF(ISBLANK(E23),"New / no prior",IF(E23>=0.2,"Accelerating",IF(E23>0,"Growing",IF(E23>=-0.1,"Stable","Declining")))) -> New / no prior | O23: Block market.txt
A24: Blockudoku: Block Puzzle Game | B24: Easybrain | C24: 239063 | D24: -20213 | E24: -0.077959 | F24: 5340.68 | G24: -410.44 | H24: -0.071367 | I24: 43734 | J24: > 3 years | K24: =C24-D24 -> 259276 | L24: =F24-G24 -> 5751.12 | M24: =IF(C24=0,"",F24/C24*1000) -> 22.340053 | N24: =IF(ISBLANK(E24),"New / no prior",IF(E24>=0.2,"Accelerating",IF(E24>0,"Growing",IF(E24>=-0.1,"Stable","Declining")))) -> Stable | O24: Block market.txt
A25: Blockbuster - Games & Social | B25: Blockbuster Group | C25: 235195 | D25: -840254 | E25: -0.781305 | F25: 2117.77 | G25: 1002.26 | H25: 0.898477 | I25: 46044 | J25: ~ 6 months | K25: =C25-D25 -> 1075449 | L25: =F25-G25 -> 1115.51 | M25: =IF(C25=0,"",F25/C25*1000) -> 9.0043156 | N25: =IF(ISBLANK(E25),"New / no prior",IF(E25>=0.2,"Accelerating",IF(E25>0,"Growing",IF(E25>=-0.1,"Stable","Declining")))) -> Declining | O25: Block market.txt
A26: Block Blast Quest | B26: KetanIreng | C26: 232263 | D26: 232263 | F26: 0 | G26: 0 | I26: 46209 | J26: ~ 1 month | K26: =C26-D26 -> 0 | L26: =F26-G26 -> 0 | M26: =IF(C26=0,"",F26/C26*1000) -> 0 | N26: =IF(ISBLANK(E26),"New / no prior",IF(E26>=0.2,"Accelerating",IF(E26>0,"Growing",IF(E26>=-0.1,"Stable","Declining")))) -> New / no prior | O26: Block market.txt
A27: Wooden Puzzle Bliss | B27: Gimica | C27: 231835 | D27: -14819 | E27: -0.06008 | F27: 0 | G27: 0 | I27: 44740 | J27: > 3 years | K27: =C27-D27 -> 246654 | L27: =F27-G27 -> 0 | M27: =IF(C27=0,"",F27/C27*1000) -> 0 | N27: =IF(ISBLANK(E27),"New / no prior",IF(E27>=0.2,"Accelerating",IF(E27>0,"Growing",IF(E27>=-0.1,"Stable","Declining")))) -> Stable | O27: Block market.txt
A28: Tangram Heaven | B28: Gimica | C28: 217267 | D28: -48937 | E28: -0.183833 | F28: 0 | G28: 0 | I28: 45446 | J28: ~ 2 years | K28: =C28-D28 -> 266204 | L28: =F28-G28 -> 0 | M28: =IF(C28=0,"",F28/C28*1000) -> 0 | N28: =IF(ISBLANK(E28),"New / no prior",IF(E28>=0.2,"Accelerating",IF(E28>0,"Growing",IF(E28>=-0.1,"Stable","Declining")))) -> Declining | O28: Block market.txt
A29: Block Puzzle | B29: Senspark | C29: 195011 | D29: -8650 | E29: -0.042473 | F29: 0 | G29: 0 | I29: 43536 | J29: > 3 years | K29: =C29-D29 -> 203661 | L29: =F29-G29 -> 0 | M29: =IF(C29=0,"",F29/C29*1000) -> 0 | N29: =IF(ISBLANK(E29),"New / no prior",IF(E29>=0.2,"Accelerating",IF(E29>0,"Growing",IF(E29>=-0.1,"Stable","Declining")))) -> Stable | O29: Block market.txt
A30: Hex Match | B30: Gimica | C30: 183642 | D30: -46591 | E30: -0.202365 | F30: 4.49 | G30: -3775.41 | H30: -0.998812 | I30: 44740 | J30: > 3 years | K30: =C30-D30 -> 230233 | L30: =F30-G30 -> 3779.9 | M30: =IF(C30=0,"",F30/C30*1000) -> 0.024449745 | N30: =IF(ISBLANK(E30),"New / no prior",IF(E30>=0.2,"Accelerating",IF(E30>0,"Growing",IF(E30>=-0.1,"Stable","Declining")))) -> Declining | O30: Block market.txt
A31: Block Puzzle Challenge | B31: Adaric Music | C31: 171917 | D31: 22522 | E31: 0.150755 | F31: 10.11 | G31: -0.34 | H31: -0.032536 | I31: 45664 | J31: ~ 2 years | K31: =C31-D31 -> 149395 | L31: =F31-G31 -> 10.45 | M31: =IF(C31=0,"",F31/C31*1000) -> 0.058807448 | N31: =IF(ISBLANK(E31),"New / no prior",IF(E31>=0.2,"Accelerating",IF(E31>0,"Growing",IF(E31>=-0.1,"Stable","Declining")))) -> Growing | O31: Block market.txt
A32: Tricky Blocks - Block Puzzle | B32: Blue Bag Studios | C32: 169554 | D32: 10911 | E32: 0.068777 | F32: 0 | G32: 0 | I32: 45943 | J32: ~ 1 year | K32: =C32-D32 -> 158643 | L32: =F32-G32 -> 0 | M32: =IF(C32=0,"",F32/C32*1000) -> 0 | N32: =IF(ISBLANK(E32),"New / no prior",IF(E32>=0.2,"Accelerating",IF(E32>0,"Growing",IF(E32>=-0.1,"Stable","Declining")))) -> Growing | O32: Block market.txt
A33: Block Puzzle: Combo Mania! | B33: Crazy Maple Studio | C33: 165920 | D33: 53062 | E33: 0.470166 | F33: 13.76 | G33: 9.17 | H33: 1.997821 | I33: 45418 | J33: ~ 3 years | K33: =C33-D33 -> 112858 | L33: =F33-G33 -> 4.59 | M33: =IF(C33=0,"",F33/C33*1000) -> 0.082931533 | N33: =IF(ISBLANK(E33),"New / no prior",IF(E33>=0.2,"Accelerating",IF(E33>0,"Growing",IF(E33>=-0.1,"Stable","Declining")))) -> Accelerating | O33: Block market.txt
A34: Block Puzzle Brick Blast | B34: Hyzap Games | C34: 165609 | D34: 41484 | E34: 0.334211 | F34: 0 | G34: 0 | I34: 43399 | J34: > 3 years | K34: =C34-D34 -> 124125 | L34: =F34-G34 -> 0 | M34: =IF(C34=0,"",F34/C34*1000) -> 0 | N34: =IF(ISBLANK(E34),"New / no prior",IF(E34>=0.2,"Accelerating",IF(E34>0,"Growing",IF(E34>=-0.1,"Stable","Declining")))) -> Accelerating | O34: Block market.txt
A35: Marble Away - Fluffy Escape | B35: CONATURE | C35: 164355 | D35: -10001 | E35: -0.05736 | F35: 6039.51 | G35: 2945.8 | H35: 0.95219 | I35: 46078 | J35: ~ 6 months | K35: =C35-D35 -> 174356 | L35: =F35-G35 -> 3093.71 | M35: =IF(C35=0,"",F35/C35*1000) -> 36.746737 | N35: =IF(ISBLANK(E35),"New / no prior",IF(E35>=0.2,"Accelerating",IF(E35>0,"Growing",IF(E35>=-0.1,"Stable","Declining")))) -> Stable | O35: Block market.txt
A36: Woodoku - Wood Block Puzzle | B36: Tripledot Studios | C36: 159969 | D36: 4185 | E36: 0.026864 | F36: 0.02 | G36: -0.03 | H36: -0.6 | I36: 43901 | J36: > 3 years | K36: =C36-D36 -> 155784 | L36: =F36-G36 -> 0.05 | M36: =IF(C36=0,"",F36/C36*1000) -> 0.00012502422 | N36: =IF(ISBLANK(E36),"New / no prior",IF(E36>=0.2,"Accelerating",IF(E36>0,"Growing",IF(E36>=-0.1,"Stable","Declining")))) -> Growing | O36: Block market.txt
A37: Blockbuster: Arcade | B37: Gimica | C37: 145947 | D37: -40508 | E37: -0.217253 | F37: 0 | G37: 0 | I37: 45602 | J37: ~ 2 years | K37: =C37-D37 -> 186455 | L37: =F37-G37 -> 0 | M37: =IF(C37=0,"",F37/C37*1000) -> 0 | N37: =IF(ISBLANK(E37),"New / no prior",IF(E37>=0.2,"Accelerating",IF(E37>0,"Growing",IF(E37>=-0.1,"Stable","Declining")))) -> Declining | O37: Block market.txt
A38: Block Jam Out: No Timer Puzzle | B38: Play2Ever Games | C38: 142076 | D38: 137062 | E38: 27.33586 | F38: 996.41 | G38: 802.43 | H38: 4.136664 | I38: 46099 | J38: ~ 6 months | K38: =C38-D38 -> 5014 | L38: =F38-G38 -> 193.98 | M38: =IF(C38=0,"",F38/C38*1000) -> 7.0132183 | N38: =IF(ISBLANK(E38),"New / no prior",IF(E38>=0.2,"Accelerating",IF(E38>0,"Growing",IF(E38>=-0.1,"Stable","Declining")))) -> Accelerating | O38: Block market.txt
A39: Block Puzzle: Stack Infinity | B39: XUFENG | C39: 140742 | D39: -7641 | E39: -0.051495 | F39: 0 | G39: 0 | I39: 45824 | J39: ~ 1 year | K39: =C39-D39 -> 148383 | L39: =F39-G39 -> 0 | M39: =IF(C39=0,"",F39/C39*1000) -> 0 | N39: =IF(ISBLANK(E39),"New / no prior",IF(E39>=0.2,"Accelerating",IF(E39>0,"Growing",IF(E39>=-0.1,"Stable","Declining")))) -> Stable | O39: Block market.txt
A40: Wood Block Jam | B40: Unico Studio | C40: 140135 | D40: 35516 | E40: 0.339479 | F40: 89272.74 | G40: 2744.81 | H40: 0.031722 | I40: 45730 | J40: ~ 2 years | K40: =C40-D40 -> 104619 | L40: =F40-G40 -> 86527.93 | M40: =IF(C40=0,"",F40/C40*1000) -> 637.04813 | N40: =IF(ISBLANK(E40),"New / no prior",IF(E40>=0.2,"Accelerating",IF(E40>0,"Growing",IF(E40>=-0.1,"Stable","Declining")))) -> Accelerating | O40: Block market.txt
...

Sheet Mahjong Data
A1: Game | B1: Publisher | C1: Downloads | D1: DL PoP Δ | E1: DL PoP % | F1: Revenue | G1: Revenue PoP Δ | H1: Revenue PoP % | I1: Release date | J1: Release age | K1: Prior downloads | L1: Prior revenue | M1: Revenue / 1k DL | N1: Momentum tag | O1: Source file
A2: Vita Mahjong | B2: Learnings | C2: 9440900 | D2: -1288660 | E2: -0.120104 | F2: 158565.75 | G2: 5449.67 | H2: 0.035592 | I2: 45261 | J2: ~ 3 years | K2: =C2-D2 -> 10729560 | L2: =F2-G2 -> 153116.08 | M2: =IF(C2=0,"",F2/C2*1000) -> 16.795618 | N2: =IF(ISBLANK(E2),"New / no prior",IF(E2>=0.2,"Accelerating",IF(E2>0,"Growing",IF(E2>=-0.1,"Stable","Declining")))) -> Declining | O2: Mahjong market (1).txt
A3: Mahjong Blast | B3: Nebula Studio | C3: 5065843 | D3: 1561100 | E3: 0.445425 | F3: 2252.46 | G3: 1850.6 | H3: 4.605086 | I3: 45831 | J3: ~ 1 year | K3: =C3-D3 -> 3504743 | L3: =F3-G3 -> 401.86 | M3: =IF(C3=0,"",F3/C3*1000) -> 0.44463676 | N3: =IF(ISBLANK(E3),"New / no prior",IF(E3>=0.2,"Accelerating",IF(E3>0,"Growing",IF(E3>=-0.1,"Stable","Declining")))) -> Accelerating | O3: Mahjong market (1).txt
A4: Mahjong Master: Daily Match | B4: Pandas of Caribbean | C4: 2347780 | D4: 631290 | E4: 0.36778 | F4: 326.39 | G4: 180.72 | H4: 1.240612 | I4: 46044 | J4: ~ 6 months | K4: =C4-D4 -> 1716490 | L4: =F4-G4 -> 145.67 | M4: =IF(C4=0,"",F4/C4*1000) -> 0.13902069 | N4: =IF(ISBLANK(E4),"New / no prior",IF(E4>=0.2,"Accelerating",IF(E4>0,"Growing",IF(E4>=-0.1,"Stable","Declining")))) -> Accelerating | O4: Mahjong market (1).txt
A5: SoEasy Mahjong: Solitaire | B5: Sofish | C5: 1166304 | D5: -630161 | E5: -0.350778 | F5: 0 | G5: 0 | I5: 46129 | J5: ~ 3 months | K5: =C5-D5 -> 1796465 | L5: =F5-G5 -> 0 | M5: =IF(C5=0,"",F5/C5*1000) -> 0 | N5: =IF(ISBLANK(E5),"New / no prior",IF(E5>=0.2,"Accelerating",IF(E5>0,"Growing",IF(E5>=-0.1,"Stable","Declining")))) -> Declining | O5: Mahjong market (1).txt
A6: Tile Mahjong Classic | B6: Sofish | C6: 740650 | D6: -317981 | E6: -0.30037 | F6: 3497.24 | G6: -755.45 | H6: -0.177641 | I6: 46070 | J6: ~ 6 months | K6: =C6-D6 -> 1058631 | L6: =F6-G6 -> 4252.69 | M6: =IF(C6=0,"",F6/C6*1000) -> 4.7218524 | N6: =IF(ISBLANK(E6),"New / no prior",IF(E6>=0.2,"Accelerating",IF(E6>0,"Growing",IF(E6>=-0.1,"Stable","Declining")))) -> Declining | O6: Mahjong market (1).txt
A7: Mahjong Traveler! | B7: Kuyisi Digital | C7: 640526 | D7: 91788 | E7: 0.167271 | F7: 0 | G7: 0 | K7: =C7-D7 -> 548738 | L7: =F7-G7 -> 0 | M7: =IF(C7=0,"",F7/C7*1000) -> 0 | N7: =IF(ISBLANK(E7),"New / no prior",IF(E7>=0.2,"Accelerating",IF(E7>0,"Growing",IF(E7>=-0.1,"Stable","Declining")))) -> Growing | O7: Mahjong market (1).txt
A8: Mahjong-Match Puzzle Games | B8: GameTree | C8: 554079 | D8: 123095 | E8: 0.285614 | F8: 177.1 | G8: -24.04 | H8: -0.119519 | I8: 44691 | J8: > 3 years | K8: =C8-D8 -> 430984 | L8: =F8-G8 -> 201.14 | M8: =IF(C8=0,"",F8/C8*1000) -> 0.31962951 | N8: =IF(ISBLANK(E8),"New / no prior",IF(E8>=0.2,"Accelerating",IF(E8>0,"Growing",IF(E8>=-0.1,"Stable","Declining")))) -> Accelerating | O8: Mahjong market (1).txt
A9: Mahjongscapes - Tile Match | B9: PARTYPOP | C9: 541008 | D9: -59592 | E9: -0.099221 | F9: 694.08 | G9: 153.67 | H9: 0.284358 | I9: 45672 | J9: ~ 2 years | K9: =C9-D9 -> 600600 | L9: =F9-G9 -> 540.41 | M9: =IF(C9=0,"",F9/C9*1000) -> 1.2829385 | N9: =IF(ISBLANK(E9),"New / no prior",IF(E9>=0.2,"Accelerating",IF(E9>0,"Growing",IF(E9>=-0.1,"Stable","Declining")))) -> Stable | O9: Mahjong market (1).txt
A10: Mahjong Cash Link | B10: Jva TTC | C10: 500239 | D10: 500239 | F10: 0 | G10: 0 | I10: 46211 | J10: ~ 1 month | K10: =C10-D10 -> 0 | L10: =F10-G10 -> 0 | M10: =IF(C10=0,"",F10/C10*1000) -> 0 | N10: =IF(ISBLANK(E10),"New / no prior",IF(E10>=0.2,"Accelerating",IF(E10>0,"Growing",IF(E10>=-0.1,"Stable","Declining")))) -> New / no prior | O10: Mahjong market (1).txt
A11: Mahjong Mingle | B11: Playful Bytes | C11: 493628 | D11: 143485 | E11: 0.40979 | F11: 0 | G11: 0 | I11: 45646 | J11: ~ 2 years | K11: =C11-D11 -> 350143 | L11: =F11-G11 -> 0 | M11: =IF(C11=0,"",F11/C11*1000) -> 0 | N11: =IF(ISBLANK(E11),"New / no prior",IF(E11>=0.2,"Accelerating",IF(E11>0,"Growing",IF(E11>=-0.1,"Stable","Declining")))) -> Accelerating | O11: Mahjong market (1).txt
A12: Mahjong Slide: Zen | B12: Playful Bytes | C12: 459472 | D12: 82604 | E12: 0.219185 | F12: 0 | G12: 0 | I12: 45908 | J12: ~ 1 year | K12: =C12-D12 -> 376868 | L12: =F12-G12 -> 0 | M12: =IF(C12=0,"",F12/C12*1000) -> 0 | N12: =IF(ISBLANK(E12),"New / no prior",IF(E12>=0.2,"Accelerating",IF(E12>0,"Growing",IF(E12>=-0.1,"Stable","Declining")))) -> Accelerating | O12: Mahjong market (1).txt
A13: Shanghai Mahjongg | B13: UniRise Digital | C13: 403181 | D13: -96726 | E13: -0.193488 | F13: 1429.25 | G13: -235.87 | H13: -0.141653 | I13: 45478 | J13: ~ 2 years | K13: =C13-D13 -> 499907 | L13: =F13-G13 -> 1665.12 | M13: =IF(C13=0,"",F13/C13*1000) -> 3.5449339 | N13: =IF(ISBLANK(E13),"New / no prior",IF(E13>=0.2,"Accelerating",IF(E13>0,"Growing",IF(E13>=-0.1,"Stable","Declining")))) -> Declining | O13: Mahjong market (1).txt
A14: Vigor Mahjong | B14: CanaryDroid | C14: 387363 | D14: 6749 | E14: 0.017732 | F14: 0 | G14: 0 | I14: 45450 | J14: ~ 2 years | K14: =C14-D14 -> 380614 | L14: =F14-G14 -> 0 | M14: =IF(C14=0,"",F14/C14*1000) -> 0 | N14: =IF(ISBLANK(E14),"New / no prior",IF(E14>=0.2,"Accelerating",IF(E14>0,"Growing",IF(E14>=-0.1,"Stable","Declining")))) -> Growing | O14: Mahjong market (1).txt
A15: Rich Mahjong Match | B15: Jva TTC | C15: 382576 | D15: 382576 | F15: 0 | G15: 0 | I15: 46211 | J15: ~ 1 month | K15: =C15-D15 -> 0 | L15: =F15-G15 -> 0 | M15: =IF(C15=0,"",F15/C15*1000) -> 0 | N15: =IF(ISBLANK(E15),"New / no prior",IF(E15>=0.2,"Accelerating",IF(E15>0,"Growing",IF(E15>=-0.1,"Stable","Declining")))) -> New / no prior | O15: Mahjong market (1).txt
A16: Mahjong Club - Solitaire Game | B16: GamoVation | C16: 341132 | D16: -19277 | E16: -0.053486 | F16: 124717.57 | G16: -25497.16 | H16: -0.169738 | I16: 44562 | J16: > 3 years | K16: =C16-D16 -> 360409 | L16: =F16-G16 -> 150214.73 | M16: =IF(C16=0,"",F16/C16*1000) -> 365.59915 | N16: =IF(ISBLANK(E16),"New / no prior",IF(E16>=0.2,"Accelerating",IF(E16>0,"Growing",IF(E16>=-0.1,"Stable","Declining")))) -> Stable | O16: Mahjong market (1).txt
A17: Fun Mahjong Match | B17: EWG STUDIO | C17: 339461 | D17: -140532 | E17: -0.292779 | F17: 327.44 | G17: 321.07 | H17: 50.403454 | I17: 46141 | J17: ~ 3 months | K17: =C17-D17 -> 479993 | L17: =F17-G17 -> 6.37 | M17: =IF(C17=0,"",F17/C17*1000) -> 0.96458798 | N17: =IF(ISBLANK(E17),"New / no prior",IF(E17>=0.2,"Accelerating",IF(E17>0,"Growing",IF(E17>=-0.1,"Stable","Declining")))) -> Declining | O17: Mahjong market (1).txt
A18: Mahjong Triple - Match 3 Tile | B18: GamoVation | C18: 330148 | D18: -110425 | E18: -0.25064 | F18: 19028.37 | G18: -247.5 | H18: -0.01284 | I18: 45610 | J18: ~ 2 years | K18: =C18-D18 -> 440573 | L18: =F18-G18 -> 19275.87 | M18: =IF(C18=0,"",F18/C18*1000) -> 57.635878 | N18: =IF(ISBLANK(E18),"New / no prior",IF(E18>=0.2,"Accelerating",IF(E18>0,"Growing",IF(E18>=-0.1,"Stable","Declining")))) -> Declining | O18: Mahjong market (1).txt
A19: Mahjong! Tile Puzzle | B19: Kuyisi Digital | C19: 329420 | D19: 267 | E19: 0.000811 | F19: 0 | G19: 0 | I19: 45846 | J19: ~ 1 year | K19: =C19-D19 -> 329153 | L19: =F19-G19 -> 0 | M19: =IF(C19=0,"",F19/C19*1000) -> 0 | N19: =IF(ISBLANK(E19),"New / no prior",IF(E19>=0.2,"Accelerating",IF(E19>0,"Growing",IF(E19>=-0.1,"Stable","Declining")))) -> Growing | O19: Mahjong market (1).txt
A20: Mahjong Pair Up | B20: summer affica | C20: 328702 | D20: -193697 | E20: -0.370784 | F20: 0 | G20: 0 | K20: =C20-D20 -> 522399 | L20: =F20-G20 -> 0 | M20: =IF(C20=0,"",F20/C20*1000) -> 0 | N20: =IF(ISBLANK(E20),"New / no prior",IF(E20>=0.2,"Accelerating",IF(E20>0,"Growing",IF(E20>=-0.1,"Stable","Declining")))) -> Declining | O20: Mahjong market (1).txt
A21: Daily Mahjong Match | B21: Big Cake Group | C21: 314174 | D21: 47599 | E21: 0.178558 | F21: 13010.05 | G21: 3410.07 | H21: 0.355216 | I21: 45692 | J21: ~ 2 years | K21: =C21-D21 -> 266575 | L21: =F21-G21 -> 9599.98 | M21: =IF(C21=0,"",F21/C21*1000) -> 41.410333 | N21: =IF(ISBLANK(E21),"New / no prior",IF(E21>=0.2,"Accelerating",IF(E21>0,"Growing",IF(E21>=-0.1,"Stable","Declining")))) -> Growing | O21: Mahjong market (1).txt
A22: Mahjong Vibe | B22: XUFENG | C22: 236565 | D22: 236565 | F22: 0 | G22: 0 | I22: 46206 | J22: ~ 1 month | K22: =C22-D22 -> 0 | L22: =F22-G22 -> 0 | M22: =IF(C22=0,"",F22/C22*1000) -> 0 | N22: =IF(ISBLANK(E22),"New / no prior",IF(E22>=0.2,"Accelerating",IF(E22>0,"Growing",IF(E22>=-0.1,"Stable","Declining")))) -> New / no prior | O22: Mahjong market (1).txt
A23: Mahjong Crush: Sorting Jam | B23: iKame | C23: 234875 | D23: 28743 | E23: 0.13944 | F23: 654800.3 | G23: -83871.14 | H23: -0.113543 | I23: 46065 | J23: ~ 6 months | K23: =C23-D23 -> 206132 | L23: =F23-G23 -> 738671.44 | M23: =IF(C23=0,"",F23/C23*1000) -> 2787.8672 | N23: =IF(ISBLANK(E23),"New / no prior",IF(E23>=0.2,"Accelerating",IF(E23>0,"Growing",IF(E23>=-0.1,"Stable","Declining")))) -> Growing | O23: Mahjong market (1).txt
A24: Zen Tiles - Mahjong Match | B24: Bluetile Games | C24: 218490 | D24: 1039 | E24: 0.004778 | F24: 134.23 | G24: -3.7 | H24: -0.026825 | I24: 45736 | J24: ~ 2 years | K24: =C24-D24 -> 217451 | L24: =F24-G24 -> 137.93 | M24: =IF(C24=0,"",F24/C24*1000) -> 0.61435306 | N24: =IF(ISBLANK(E24),"New / no prior",IF(E24>=0.2,"Accelerating",IF(E24>0,"Growing",IF(E24>=-0.1,"Stable","Declining")))) -> Growing | O24: Mahjong market (1).txt
A25: Zen Garden Mahjong | B25: AMG DevBM | C25: 164028 | D25: 140226 | E25: 5.891354 | F25: 0 | G25: 0 | I25: 46178 | J25: ~ 3 months | K25: =C25-D25 -> 23802 | L25: =F25-G25 -> 0 | M25: =IF(C25=0,"",F25/C25*1000) -> 0 | N25: =IF(ISBLANK(E25),"New / no prior",IF(E25>=0.2,"Accelerating",IF(E25>0,"Growing",IF(E25>=-0.1,"Stable","Declining")))) -> Accelerating | O25: Mahjong market (1).txt

Sheet Phương pháp
A1: PHƯƠNG PHÁP & HƯỚNG DẪN RESEARCH
A3: MỤC TIÊU | B3: Đánh giá scale, momentum, monetization proxy và cơ hội concept Mahjong × Block.
A4: Đối tượng sử dụng | B4: Game designer; dùng để shortlist đối thủ, đặt hypothesis và lên kế hoạch teardown.
A5: Đơn vị phân tích | B5: Một dòng = một game trong snapshot nguồn.
A6: NGUỒN 1 | B6: Block market.txt
A7: NGUỒN 2 | B7: Mahjong market (1).txt
A8: Ngày dựng workbook | B8: 46250
A10: CHỈ SỐ | B10: ĐỊNH NGHĨA TRONG WORKBOOK | C10: CẢNH BÁO
A11: Downloads | B11: Downloads (Absolute) từ nguồn | C11: Không rõ geography/store/kỳ đo
A12: DL PoP Δ | B12: Chênh lệch downloads so với kỳ trước | C12: Kỳ PoP không được mô tả
A13: DL PoP % | B13: Tỷ lệ thay đổi downloads từ nguồn | C13: Blank thường là game mới/no prior
A14: Revenue | B14: Revenue (Absolute) từ nguồn | C14: Không rõ currency; 0 có thể là missing
A15: Revenue / 1k DL | B15: Revenue / Downloads × 1.000 | C15: Proxy monetization, không phải ARPU
A16: Weighted DL growth | B16: Tổng DL PoP Δ / tổng prior downloads | C16: Giảm ảnh hưởng game có base nhỏ
A17: Positive growth share | B17: Số game DL growth > 0 / số game có growth | C17: Loại game thiếu growth khỏi mẫu số
A18: Top 5 concentration | B18: Tổng downloads 5 game đầu / tổng downloads | C18: Đo mức phụ thuộc hit
A19: Recent releases | B19: Release date trong 365 ngày gần nhất | C19: Dùng TODAY() của Excel
A21: OPPORTUNITY SCORE | B21: TRỌNG SỐ MẶC ĐỊNH | C21: LOGIC | D21: RỦI RO
A22: Traction | B22: 0.35 | C22: Log-normalized downloads trong toàn bộ 73 game | D22: Ưu tiên game lớn
A23: Momentum | B23: 0.3 | C23: Map -25%→0, +100%→100; cap ngoài biên; blank→50 | D23: Outlier base nhỏ vẫn cần review
A24: Monetization | B24: 0.25 | C24: Log-normalized revenue/1k downloads | D24: Revenue 0/missing làm giảm điểm
A25: Recency | B25: 0.1 | C25: 100 điểm khi mới; giảm về 0 sau 3 năm; blank→30 | D25: Ngày nguồn có thể thiếu
A26: Total | B26: 1 | C26: SUMPRODUCT 4 dimension với trọng số Shortlist!B2:E2 | D26: Score để ưu tiên research, không phải dự báo hit
A28: WORKFLOW GỢI Ý | B28: HÀNH ĐỘNG
A29: 1. Lọc | B29: Shortlist: lọc Rank <= 15 và Research status = Chưa review.
A30: 2. Chọn lens | B30: Chỉnh trọng số theo câu hỏi: scale, trend, monetization hay new entrants.
A31: 3. Teardown | B31: Review store page, FTUE, core loop, fail state, meta, economy, ads/IAP.
A32: 4. Ghi evidence | B32: Cập nhật Research status và Notes ngay trên từng game.
A33: 5. So sánh | B33: Chọn 3 Block + 3 Mahjong để lập feature matrix.
A34: 6. Prototype | B34: Test cùng một core với theme abstract vs Mahjong.
A35: 7. Kết luận | B35: Chỉ ra evidence, assumption, dependency và test tiếp theo.
A37: QUY TẮC DIỄN GIẢI | B37: Không coi tổng trong file là market size tuyệt đối; đây là snapshot research.
A38: LƯU Ý | B38: Các insight cần được xác minh thêm bằng store page, gameplay và dữ liệu retention/monetization thực tế.

Sheet Tổng hợp Interpret
A1: TỔNG HỢP DỮ LIỆU CÓ THỂ INTERPRET
A2: Nguồn: Bài tập Mahjong × Block Puzzle + AILog_15082026 | Tách rõ evidence, interpretation và khoảng trống dữ liệu
A4: INTERPRETATION TỪ DỮ LIỆU HIỆN CÓ
A5: Nhóm dữ liệu | B5: Evidence quan sát được | C5: Interpretation có thể rút ra | D5: Tin cậy | E5: Tác động / ưu tiên thiết kế | F5: Cần kiểm chứng | G5: Nguồn
A6: Core loop | B6: Mahjong và Block phải cùng tham gia một core loop và tác động lẫn nhau. | C6: Giá trị lai nằm ở quan hệ nhân–quả giữa hai hệ, không phải số lượng mechanic. | D6: Cao | E6: P0 — mô tả rõ state/resource nào chuyển từ hệ A sang B và ngược lại. | F6: Prototype có còn thú vị nếu bỏ một trong hai hệ? | G6: PDF tr.1–2, B1
A7: Tỷ trọng hai hệ | B7: Không bắt buộc chia đều 50/50 nhưng cả hai phải thiết yếu. | C7: Có thể thiết kế bất đối xứng; một hệ tạo lựa chọn, hệ kia giải quyết hệ quả. | D7: Cao | E7: P0 — chọn vai trò riêng cho từng hệ thay vì ép thời lượng bằng nhau. | F7: Người chơi có nhận ra vai trò thiết yếu của cả hai? | G7: PDF tr.2
A8: Hook / quyết định mới | B8: Rubric B1 yêu cầu tạo quyết định mới và hook được khai thác đủ sâu. | C8: Hook cần được diễn đạt như một quyết định lặp lại, không chỉ là theme hoặc gimmick. | D8: Cao | E8: P0 — viết câu: “Người chơi chọn X trong Mahjong để đổi Y trong Block, chấp nhận trade-off Z”. | F8: Quyết định có nhiều phương án hợp lệ và trade-off thật không? | G8: PDF tr.1, tr.4 B1
A9: 50 màn & beat chart | B9: Có 50 màn hoàn chỉnh; beat chart bao phủ toàn bộ 50 màn; pacing có chủ đích. | C9: Beat chart là công cụ sản xuất và kiểm soát difficulty, không chỉ tài liệu nộp. | D9: Cao | E9: P0 — gắn từng level với mục tiêu dạy/luyện/kết hợp/kiểm tra. | F9: Độ khó tăng do kỹ năng mới hay chỉ do thêm chướng ngại? | G9: PDF tr.2–4, B3
A10: Onboarding | B10: Người mới phải tự hiểu mục tiêu và thao tác; màn đầu dạy bằng chơi, không phụ thuộc chữ. | C10: Mức dễ hiểu phải được chứng minh bằng hành vi người chơi mới. | D10: Cao | E10: P0 — playtest first-time user; đo thời gian hiểu mục tiêu và lỗi thao tác đầu. | F10: Người chơi mới hoàn thành màn 1 mà không được hướng dẫn miệng? | G10: PDF tr.4 B2
A11: Gate kỹ thuật | B11: Build không mở/không chơi được: A = 0 và không chấm B. | C11: Ổn định build là điều kiện mở khóa phần lớn điểm, không phải hạng mục polish cuối. | D11: Cao | E11: P0 — tạo vertical slice chạy mobile sớm; smoke test sau mỗi thay đổi lớn. | F11: Mở offline, không mạng, trên ít nhất 2 kích thước điện thoại? | G11: PDF tr.4
